[2025-09-22T00:06:27.398+0000] {taskinstance.py:1956} INFO - Dependencies all met for dep_context=non-requeueable deps ti=<TaskInstance: ingestao_bronze.trigger_processamento_silver manual__2025-09-22T00:05:06.559499+00:00 [queued]>
[2025-09-22T00:06:27.419+0000] {taskinstance.py:1956} INFO - Dependencies all met for dep_context=requeueable deps ti=<TaskInstance: ingestao_bronze.trigger_processamento_silver manual__2025-09-22T00:05:06.559499+00:00 [queued]>
[2025-09-22T00:06:27.419+0000] {taskinstance.py:2170} INFO - Starting attempt 1 of 2
[2025-09-22T00:06:27.440+0000] {taskinstance.py:2191} INFO - Executing <Task(TriggerDagRunOperator): trigger_processamento_silver> on 2025-09-22 00:05:06.559499+00:00
[2025-09-22T00:06:27.454+0000] {standard_task_runner.py:60} INFO - Started process 272 to run task
[2025-09-22T00:06:27.474+0000] {standard_task_runner.py:87} INFO - Running: ['***', 'tasks', 'run', 'ingestao_bronze', 'trigger_processamento_silver', 'manual__2025-09-22T00:05:06.559499+00:00', '--job-id', '27', '--raw', '--subdir', 'DAGS_FOLDER/ingestao_bronze.py', '--cfg-path', '/tmp/tmpax_z1hcj']
[2025-09-22T00:06:27.476+0000] {standard_task_runner.py:88} INFO - Job 27: Subtask trigger_processamento_silver
[2025-09-22T00:06:27.576+0000] {task_command.py:423} INFO - Running <TaskInstance: ingestao_bronze.trigger_processamento_silver manual__2025-09-22T00:05:06.559499+00:00 [running]> on host e833383cbb8e
[2025-09-22T00:06:27.746+0000] {taskinstance.py:2480} INFO - Exporting env vars: AIRFLOW_CTX_DAG_OWNER='***' AIRFLOW_CTX_DAG_ID='ingestao_bronze' AIRFLOW_CTX_TASK_ID='trigger_processamento_silver' AIRFLOW_CTX_EXECUTION_DATE='2025-09-22T00:05:06.559499+00:00' AIRFLOW_CTX_TRY_NUMBER='1' AIRFLOW_CTX_DAG_RUN_ID='manual__2025-09-22T00:05:06.559499+00:00'
[2025-09-22T00:06:27.807+0000] {taskinstance.py:2698} ERROR - Task failed with exception
Traceback (most recent call last):
  File "/home/airflow/.local/lib/python3.8/site-packages/airflow/models/taskinstance.py", line 433, in _execute_task
    result = execute_callable(context=context, **execute_callable_kwargs)
  File "/home/airflow/.local/lib/python3.8/site-packages/airflow/operators/trigger_dagrun.py", line 165, in execute
    dag_run = trigger_dag(
  File "/home/airflow/.local/lib/python3.8/site-packages/airflow/api/common/trigger_dag.py", line 125, in trigger_dag
    triggers = _trigger_dag(
  File "/home/airflow/.local/lib/python3.8/site-packages/airflow/api/common/trigger_dag.py", line 55, in _trigger_dag
    raise DagNotFound(f"Dag id {dag_id} not found")
airflow.exceptions.DagNotFound: Dag id processamento_silver not found
[2025-09-22T00:06:27.811+0000] {taskinstance.py:1138} INFO - Marking task as UP_FOR_RETRY. dag_id=ingestao_bronze, task_id=trigger_processamento_silver, execution_date=20250922T000506, start_date=20250922T000627, end_date=20250922T000627
[2025-09-22T00:06:27.843+0000] {standard_task_runner.py:107} ERROR - Failed to execute job 27 for task trigger_processamento_silver (Dag id processamento_silver not found; 272)
[2025-09-22T00:06:27.889+0000] {local_task_job_runner.py:234} INFO - Task exited with return code 1
[2025-09-22T00:06:27.928+0000] {taskinstance.py:3280} INFO - 0 downstream tasks scheduled from follow-on schedule check
